<?xml version="1.0"?>
<robot xmlns:xacro="http://ros.org/wiki/xacro">

  <xacro:include filename="$(find agv_eval_description)/urdf/common.xacro"/>

  <xacro:property name="wheel_radius" value="${0.150/2}"/>
  <xacro:property name="wheel_length" value="0.035"/>
  <xacro:property name="wheel_mass" value="0.5"/>

  <xacro:macro name="wheel_v0" params="prefix parent *joint_origin *joint_axis">
    <joint name="${prefix}_wheel_joint" type="continuous">
      <xacro:insert_block name="joint_origin"/>
      <parent link="${parent}"/>
      <child link="${prefix}_wheel_link"/>
      <xacro:insert_block name="joint_axis"/>
    </joint>

    <link name="${prefix}_wheel_link">
      <visual>
        <origin xyz="0 0 0" rpy="${-M_PI/2} 0 0"/>
        <geometry>
          <cylinder radius="${wheel_radius}" length="${wheel_length}"/>
        </geometry>
      </visual>
      <collision>
        <origin xyz="0 0 0" rpy="${-M_PI/2} 0 0"/>
        <geometry>
          <cylinder radius="${wheel_radius}" length="${wheel_length}"/>
        </geometry>
      </collision>
      <inertial>
        <origin xyz="0 0 0" rpy="${-M_PI/2} 0 0"/>
        <xacro:cylinder_inertial mass="${wheel_mass}" radius="${wheel_radius}" length="${wheel_length}"/>
      </inertial>
    </link>
  </xacro:macro>

  <xacro:macro name="wheel_gazebo_v0" params="prefix">
    <gazebo reference="${prefix}_wheel_link">
      <selfCollide>false</selfCollide>
      <mu1 value="2.5" />
      <mu2 value="2.5" />
      <kp value="500000" />
      <kd value="10" />
      <!--fdir1 value="1 0 0"/-->
      <material>Gazebo/Black</material>
    </gazebo>
  </xacro:macro>

  <xacro:macro name="wheel_trans_v0" params="prefix">
    <transmission name="${prefix}_wheel_trans">
        <type>transmission_interface/SimpleTransmission</type>
        <joint name="${prefix}_wheel_joint">
      <hardwareInterface>hardware_interface/VelocityJointInterface</hardwareInterface>
        </joint>
      <actuator name="${prefix}_wheel_motor">
      <hardwareInterface>hardware_interface/VelocityJointInterface</hardwareInterface>
      <mechanicalReduction>30</mechanicalReduction>
        </actuator>
    </transmission>
  </xacro:macro>

</robot>
