<?xml version="1.0"?>
<robot xmlns:xacro="http://ros.org/wiki/xacro">

  <xacro:include filename="$(find agv_eval_description)/sample3/wheel/wheel.urdf.xacro"/>
  <xacro:include filename="$(find agv_eval_description)/urdf/common.xacro"/>
  <xacro:include filename="$(find agv_eval_description)/sample3/caster/caster.urdf.xacro"/>

  <xacro:property name="caster_radius" value="${0.10/2}"/>
  <xacro:property name="caster_length" value="0.04"/>
  <xacro:property name="caster_mass" value="0.5"/>

  <xacro:macro name="front_unit_v0" params="prefix parent *joint_origin *wheel_origin">
    <joint name="${prefix}_arm_joint" type="revolute">
      <xacro:insert_block name="joint_origin"/>
      <parent link="${parent}"/>
      <child link="${prefix}_arm_link"/>
      <axis xyz="0 1 0"/>
      <limit lower="-0.5" upper="0.5" effort="0" velocity="0"/>
      <dynamics damping="0.7"/>
    </joint>
    <link name="${prefix}_arm_link">
      <visual>
        <origin xyz="0 0 0 " rpy="0 0 0"/>
        <geometry>
          <box size="0.035 0.07 0.43"/>
        </geometry>
      </visual>
      <collision>
        <origin xyz="0 0 0" rpy="0 0 0"/>
        <geometry>
          <box size="0.035 0.07 0.43"/>
        </geometry>
      </collision>
      <inertial>
        <origin xyz="0 0 0" rpy="0 0 0"/>
        <xacro:box_inertial mass="0.2" height="0.1" width="0.05" depth="0.05"/>
      </inertial>
    </link>

    <xacro:wheel_v0 prefix="${prefix}" parent="${prefix}_arm_link">
      <xacro:insert_block name="wheel_origin"/>
      <!--origin xyz="0.086 0 -0.14"/-->
      <axis xyz="0 1 0"/>
    </xacro:wheel_v0>

    <xacro:caster_v0 prefix="${prefix}" parent="${prefix}_arm_link">
      <origin xyz="0.01 0 0.2" rpy="0 -1.57 0"/>
    </xacro:caster_v0>

  </xacro:macro>

  <xacro:macro name="caster_gazebo_v0" params="prefix">
    <gazebo reference="${prefix}_caster_link">
      <selfCollide>false</selfCollide>
      <mu1 value="2.5" />
      <mu2 value="2.5" />
      <kp value="1e7" />
      <kd value="1" />
      <!--fdir1 value="1 0 0"/-->
      <material>Gazebo/Black</material>
    </gazebo>
  </xacro:macro>

</robot>
